2024-02-23 16:16:18.446 | INFO     | __main__:__create_log_file:85 - /app/src/logs/server_yolo_analys_log/runtime_server_yolo_analys_2024-2-23-16-16-18.log
2024-02-23 16:16:18.447 | INFO     | __main__:start:182 - Start server_yolo_analys
2024-02-23 16:22:16.680 | INFO     | asyncio.events:_run:80 - An error has been caught in function '_run', process 'MainProcess' (375), thread 'MainThread' (140344575262720):
Traceback (most recent call last):

  File "/app/src/server_yolo_analys.py", line 192, in <module>
    run(sya.start())
    │   │   └ <function server_yolo_analys.start at 0x7fa37e126ca0>
    │   └ <__main__.server_yolo_analys object at 0x7fa37e122290>
    └ <function run at 0x7fa483e737e0>

  File "/usr/lib/python3.11/asyncio/runners.py", line 190, in run
    return runner.run(main)
           │      │   └ <coroutine object server_yolo_analys.start at 0x7fa47322b940>
           │      └ <function Runner.run at 0x7fa483cc7100>
           └ <asyncio.runners.Runner object at 0x7fa37e7f3650>
  File "/usr/lib/python3.11/asyncio/runners.py", line 118, in run
    return self._loop.run_until_complete(task)
           │    │     │                  └ <Task pending name='Task-1' coro=<server_yolo_analys.start() running at /usr/local/lib/python3.11/dist-packages/loguru/_logge...
           │    │     └ <function BaseEventLoop.run_until_complete at 0x7fa483cc4d60>
           │    └ <_UnixSelectorEventLoop running=True closed=False debug=False>
           └ <asyncio.runners.Runner object at 0x7fa37e7f3650>
  File "/usr/lib/python3.11/asyncio/base_events.py", line 640, in run_until_complete
    self.run_forever()
    │    └ <function BaseEventLoop.run_forever at 0x7fa483cc4cc0>
    └ <_UnixSelectorEventLoop running=True closed=False debug=False>
  File "/usr/lib/python3.11/asyncio/base_events.py", line 607, in run_forever
    self._run_once()
    │    └ <function BaseEventLoop._run_once at 0x7fa483cc6ac0>
    └ <_UnixSelectorEventLoop running=True closed=False debug=False>
  File "/usr/lib/python3.11/asyncio/base_events.py", line 1922, in _run_once
    handle._run()
    │      └ <function Handle._run at 0x7fa483e29080>
    └ <Handle <TaskStepMethWrapper object at 0x7fa4734a25f0>()>
> File "/usr/lib/python3.11/asyncio/events.py", line 80, in _run
    self._context.run(self._callback, *self._args)
    │    │            │    │           │    └ <member '_args' of 'Handle' objects>
    │    │            │    │           └ <Handle <TaskStepMethWrapper object at 0x7fa4734a25f0>()>
    │    │            │    └ <member '_callback' of 'Handle' objects>
    │    │            └ <Handle <TaskStepMethWrapper object at 0x7fa4734a25f0>()>
    │    └ <member '_context' of 'Handle' objects>
    └ <Handle <TaskStepMethWrapper object at 0x7fa4734a25f0>()>

  File "/app/src/server_yolo_analys.py", line 187, in start
    query.awaitTermination()
    │     └ <function StreamingQuery.awaitTermination at 0x7fa37e1db240>
    └ <pyspark.sql.streaming.query.StreamingQuery object at 0x7fa47301e810>

  File "/usr/local/lib/python3.11/dist-packages/pyspark/sql/streaming/query.py", line 221, in awaitTermination
    return self._jsq.awaitTermination()
           │    └ JavaObject id=o44
           └ <pyspark.sql.streaming.query.StreamingQuery object at 0x7fa47301e810>
  File "/usr/local/lib/python3.11/dist-packages/py4j/java_gateway.py", line 1322, in __call__
    return_value = get_return_value(
                   └ <function capture_sql_exception.<locals>.deco at 0x7fa470890fe0>
  File "/usr/local/lib/python3.11/dist-packages/pyspark/errors/exceptions/captured.py", line 179, in deco
    return f(*a, **kw)
           │  │    └ {}
           │  └ ('x', <py4j.clientserver.JavaClient object at 0x7fa37e199d90>, 'o44', 'awaitTermination')
           └ <function get_return_value at 0x7fa37e5b9b20>
  File "/usr/local/lib/python3.11/dist-packages/py4j/protocol.py", line 334, in get_return_value
    raise Py4JError(
          └ <class 'py4j.protocol.Py4JError'>

py4j.protocol.Py4JError: An error occurred while calling o44.awaitTermination
2024-02-23 16:22:16.684 | INFO     | __main__:__exit__:58 - End work server_yolo_analys
