2024-02-21 01:15:09.878 | INFO     | __main__:__create_log_file:47 - /app/ubuntu/app/src/logs/server_yolo_analys_log/runtime_server_yolo_analys_2024-2-21-1-15-9.log
2024-02-21 01:15:09.879 | INFO     | __main__:start:113 - Start server_yolo_analys
2024-02-21 01:17:38.178 | INFO     | asyncio.events:_run:80 - An error has been caught in function '_run', process 'MainProcess' (7732), thread 'MainThread' (140030258147328):
Traceback (most recent call last):

  File "/app/ubuntu/app/src/server_yolo_analys.py", line 122, in <module>
    run(sya.start())
    │   │   └ <function server_yolo_analys.start at 0x7f5a4f50b560>
    │   └ <__main__.server_yolo_analys object at 0x7f5a4f514050>
    └ <function run at 0x7f5b55736b60>

  File "/usr/lib/python3.11/asyncio/runners.py", line 190, in run
    return runner.run(main)
           │      │   └ <coroutine object server_yolo_analys.start at 0x7f5b3a060140>
           │      └ <function Runner.run at 0x7f5b550d93a0>
           └ <asyncio.runners.Runner object at 0x7f5a4fa7e850>
  File "/usr/lib/python3.11/asyncio/runners.py", line 118, in run
    return self._loop.run_until_complete(task)
           │    │     │                  └ <Task pending name='Task-1' coro=<server_yolo_analys.start() running at /usr/local/lib/python3.11/dist-packages/loguru/_logge...
           │    │     └ <function BaseEventLoop.run_until_complete at 0x7f5b550d6fc0>
           │    └ <_UnixSelectorEventLoop running=True closed=False debug=False>
           └ <asyncio.runners.Runner object at 0x7f5a4fa7e850>
  File "/usr/lib/python3.11/asyncio/base_events.py", line 640, in run_until_complete
    self.run_forever()
    │    └ <function BaseEventLoop.run_forever at 0x7f5b550d6f20>
    └ <_UnixSelectorEventLoop running=True closed=False debug=False>
  File "/usr/lib/python3.11/asyncio/base_events.py", line 607, in run_forever
    self._run_once()
    │    └ <function BaseEventLoop._run_once at 0x7f5b550d8d60>
    └ <_UnixSelectorEventLoop running=True closed=False debug=False>
  File "/usr/lib/python3.11/asyncio/base_events.py", line 1922, in _run_once
    handle._run()
    │      └ <function Handle._run at 0x7f5b55737380>
    └ <Handle <TaskStepMethWrapper object at 0x7f5b41995570>()>
> File "/usr/lib/python3.11/asyncio/events.py", line 80, in _run
    self._context.run(self._callback, *self._args)
    │    │            │    │           │    └ <member '_args' of 'Handle' objects>
    │    │            │    │           └ <Handle <TaskStepMethWrapper object at 0x7f5b41995570>()>
    │    │            │    └ <member '_callback' of 'Handle' objects>
    │    │            └ <Handle <TaskStepMethWrapper object at 0x7f5b41995570>()>
    │    └ <member '_context' of 'Handle' objects>
    └ <Handle <TaskStepMethWrapper object at 0x7f5b41995570>()>

  File "/app/ubuntu/app/src/server_yolo_analys.py", line 118, in start
    query.awaitTermination()
    │     └ <function StreamingQuery.awaitTermination at 0x7f5a4f5bfc40>
    └ <pyspark.sql.streaming.query.StreamingQuery object at 0x7f5b3a164a50>

  File "/usr/local/lib/python3.11/dist-packages/pyspark/sql/streaming/query.py", line 221, in awaitTermination
    return self._jsq.awaitTermination()
           │    └ JavaObject id=o46
           └ <pyspark.sql.streaming.query.StreamingQuery object at 0x7f5b3a164a50>
  File "/usr/local/lib/python3.11/dist-packages/py4j/java_gateway.py", line 1322, in __call__
    return_value = get_return_value(
                   └ <function capture_sql_exception.<locals>.deco at 0x7f5a6352aac0>
  File "/usr/local/lib/python3.11/dist-packages/pyspark/errors/exceptions/captured.py", line 179, in deco
    return f(*a, **kw)
           │  │    └ {}
           │  └ ('x', <py4j.clientserver.JavaClient object at 0x7f5a4fced410>, 'o46', 'awaitTermination')
           └ <function get_return_value at 0x7f5a4faaa2a0>
  File "/usr/local/lib/python3.11/dist-packages/py4j/protocol.py", line 334, in get_return_value
    raise Py4JError(
          └ <class 'py4j.protocol.Py4JError'>

py4j.protocol.Py4JError: An error occurred while calling o46.awaitTermination
2024-02-21 01:17:38.183 | INFO     | __main__:__exit__:51 - End work server_yolo_analys
