2024-02-21 00:57:48.514 | INFO     | __main__:__create_log_file:46 - /app/ubuntu/app/src/logs/server_yolo_analys_log/runtime_server_yolo_analys_2024-2-21-0-57-48.log
2024-02-21 00:57:48.516 | INFO     | __main__:start:111 - Start server_yolo_analys
2024-02-21 00:57:55.912 | ERROR    | __main__:__analys_frame:106 - a bytes-like object is required, not 'NoneType'
2024-02-21 00:58:01.990 | ERROR    | __main__:__analys_frame:106 - a bytes-like object is required, not 'NoneType'
2024-02-21 00:58:22.142 | INFO     | asyncio.events:_run:80 - An error has been caught in function '_run', process 'MainProcess' (29066), thread 'MainThread' (140526833225728):
Traceback (most recent call last):

  File "/app/ubuntu/app/src/server_yolo_analys.py", line 120, in <module>
    run(sya.start())
    │   │   └ <function server_yolo_analys.start at 0x7fcded7d36a0>
    │   └ <__main__.server_yolo_analys object at 0x7fcded7e0910>
    └ <function run at 0x7fcef3a1ac00>

  File "/usr/lib/python3.11/asyncio/runners.py", line 190, in run
    return runner.run(main)
           │      │   └ <coroutine object server_yolo_analys.start at 0x7fce016c4140>
           │      └ <function Runner.run at 0x7fcef3391440>
           └ <asyncio.runners.Runner object at 0x7fcdedd3f650>
  File "/usr/lib/python3.11/asyncio/runners.py", line 118, in run
    return self._loop.run_until_complete(task)
           │    │     │                  └ <Task pending name='Task-1' coro=<server_yolo_analys.start() running at /usr/local/lib/python3.11/dist-packages/loguru/_logge...
           │    │     └ <function BaseEventLoop.run_until_complete at 0x7fcef338f060>
           │    └ <_UnixSelectorEventLoop running=True closed=False debug=False>
           └ <asyncio.runners.Runner object at 0x7fcdedd3f650>
  File "/usr/lib/python3.11/asyncio/base_events.py", line 640, in run_until_complete
    self.run_forever()
    │    └ <function BaseEventLoop.run_forever at 0x7fcef338efc0>
    └ <_UnixSelectorEventLoop running=True closed=False debug=False>
  File "/usr/lib/python3.11/asyncio/base_events.py", line 607, in run_forever
    self._run_once()
    │    └ <function BaseEventLoop._run_once at 0x7fcef3390e00>
    └ <_UnixSelectorEventLoop running=True closed=False debug=False>
  File "/usr/lib/python3.11/asyncio/base_events.py", line 1922, in _run_once
    handle._run()
    │      └ <function Handle._run at 0x7fcef3a1b420>
    └ <Handle <TaskStepMethWrapper object at 0x7fcedd41cfd0>()>
> File "/usr/lib/python3.11/asyncio/events.py", line 80, in _run
    self._context.run(self._callback, *self._args)
    │    │            │    │           │    └ <member '_args' of 'Handle' objects>
    │    │            │    │           └ <Handle <TaskStepMethWrapper object at 0x7fcedd41cfd0>()>
    │    │            │    └ <member '_callback' of 'Handle' objects>
    │    │            └ <Handle <TaskStepMethWrapper object at 0x7fcedd41cfd0>()>
    │    └ <member '_context' of 'Handle' objects>
    └ <Handle <TaskStepMethWrapper object at 0x7fcedd41cfd0>()>

  File "/app/ubuntu/app/src/server_yolo_analys.py", line 116, in start
    query.awaitTermination()
    │     └ <function StreamingQuery.awaitTermination at 0x7fcded88bd80>
    └ <pyspark.sql.streaming.query.StreamingQuery object at 0x7fce017a2410>

  File "/usr/local/lib/python3.11/dist-packages/pyspark/sql/streaming/query.py", line 221, in awaitTermination
    return self._jsq.awaitTermination()
           │    └ JavaObject id=o46
           └ <pyspark.sql.streaming.query.StreamingQuery object at 0x7fce017a2410>
  File "/usr/local/lib/python3.11/dist-packages/py4j/java_gateway.py", line 1322, in __call__
    return_value = get_return_value(
                   └ <function capture_sql_exception.<locals>.deco at 0x7fcdec332200>
  File "/usr/local/lib/python3.11/dist-packages/pyspark/errors/exceptions/captured.py", line 179, in deco
    return f(*a, **kw)
           │  │    └ {}
           │  └ ('x', <py4j.clientserver.JavaClient object at 0x7fcded870790>, 'o46', 'awaitTermination')
           └ <function get_return_value at 0x7fcdedd7a3e0>
  File "/usr/local/lib/python3.11/dist-packages/py4j/protocol.py", line 334, in get_return_value
    raise Py4JError(
          └ <class 'py4j.protocol.Py4JError'>

py4j.protocol.Py4JError: An error occurred while calling o46.awaitTermination
2024-02-21 00:58:22.146 | INFO     | __main__:__exit__:50 - End work server_yolo_analys
