2024-02-19 19:15:43.880 | INFO     | __main__:create_log_file:38 - /app/ubuntu/app/src/logs/server_get_vidio_log/runtime_server_get_vidio_2024-2-19-19-15-43.log
2024-02-19 19:15:43.880 | INFO     | __main__:start_server_get_vidio:61 - Start get_video_server
2024-02-19 19:16:07.330 | INFO     | asyncio.events:_run:80 - An error has been caught in function '_run', process 'MainProcess' (4133), thread 'MainThread' (140288304308224):
Traceback (most recent call last):

  File "/app/ubuntu/app/src/server_get_video.py", line 75, in <module>
    run(start_server_get_vidio())
    │   └ <function start_server_get_vidio at 0x7f97352318a0>
    └ <function run at 0x7f9769e4f420>

  File "/usr/lib/python3.11/asyncio/runners.py", line 190, in run
    return runner.run(main)
           │      │   └ <coroutine object start_server_get_vidio at 0x7f973537b640>
           │      └ <function Runner.run at 0x7f9769c9ad40>
           └ <asyncio.runners.Runner object at 0x7f973544b2d0>
  File "/usr/lib/python3.11/asyncio/runners.py", line 118, in run
    return self._loop.run_until_complete(task)
           │    │     │                  └ <Task pending name='Task-1' coro=<start_server_get_vidio() running at /usr/local/lib/python3.11/dist-packages/loguru/_logger....
           │    │     └ <function BaseEventLoop.run_until_complete at 0x7f9769c989a0>
           │    └ <_UnixSelectorEventLoop running=True closed=False debug=False>
           └ <asyncio.runners.Runner object at 0x7f973544b2d0>
  File "/usr/lib/python3.11/asyncio/base_events.py", line 640, in run_until_complete
    self.run_forever()
    │    └ <function BaseEventLoop.run_forever at 0x7f9769c98900>
    └ <_UnixSelectorEventLoop running=True closed=False debug=False>
  File "/usr/lib/python3.11/asyncio/base_events.py", line 607, in run_forever
    self._run_once()
    │    └ <function BaseEventLoop._run_once at 0x7f9769c9a700>
    └ <_UnixSelectorEventLoop running=True closed=False debug=False>
  File "/usr/lib/python3.11/asyncio/base_events.py", line 1922, in _run_once
    handle._run()
    │      └ <function Handle._run at 0x7f9769dfccc0>
    └ <Handle <TaskStepMethWrapper object at 0x7f973521f0d0>()>
> File "/usr/lib/python3.11/asyncio/events.py", line 80, in _run
    self._context.run(self._callback, *self._args)
    │    │            │    │           │    └ <member '_args' of 'Handle' objects>
    │    │            │    │           └ <Handle <TaskStepMethWrapper object at 0x7f973521f0d0>()>
    │    │            │    └ <member '_callback' of 'Handle' objects>
    │    │            └ <Handle <TaskStepMethWrapper object at 0x7f973521f0d0>()>
    │    └ <member '_context' of 'Handle' objects>
    └ <Handle <TaskStepMethWrapper object at 0x7f973521f0d0>()>

  File "/app/ubuntu/app/src/server_get_video.py", line 72, in start_server_get_vidio
    query_cons.awaitTermination()
    │          └ <function StreamingQuery.awaitTermination at 0x7f97354fd940>
    └ <pyspark.sql.streaming.query.StreamingQuery object at 0x7f9735110bd0>

  File "/usr/local/lib/python3.11/dist-packages/pyspark/sql/streaming/query.py", line 221, in awaitTermination
    return self._jsq.awaitTermination()
           │    └ JavaObject id=o44
           └ <pyspark.sql.streaming.query.StreamingQuery object at 0x7f9735110bd0>
  File "/usr/local/lib/python3.11/dist-packages/py4j/java_gateway.py", line 1322, in __call__
    return_value = get_return_value(
                   └ <function capture_sql_exception.<locals>.deco at 0x7f9735593a60>
  File "/usr/local/lib/python3.11/dist-packages/pyspark/errors/exceptions/captured.py", line 179, in deco
    return f(*a, **kw)
           │  │    └ {}
           │  └ ('x', <py4j.clientserver.JavaClient object at 0x7f97352bbf10>, 'o44', 'awaitTermination')
           └ <function get_return_value at 0x7f97357e5d00>
  File "/usr/local/lib/python3.11/dist-packages/py4j/protocol.py", line 334, in get_return_value
    raise Py4JError(
          └ <class 'py4j.protocol.Py4JError'>

py4j.protocol.Py4JError: An error occurred while calling o44.awaitTermination
